<?xml version="1.0"?>
<robot xmlns:xacro="http://www.ros.org/wiki/xacro" >

    <xacro:include filename="inertial_macros.xacro"/>

    <xacro:property name="chassis_length" value="0.80"/>
    <xacro:property name="chassis_width" value="0.58"/>
    <xacro:property name="chassis_height" value="0.09"/>
    <xacro:property name="chassis_mass" value="1.0"/>
    <xacro:property name="wheel_radius" value="0.1"/>
    <xacro:property name="wheel_thickness" value="0.04"/>
    <xacro:property name="wheel_mass" value="0.05"/>
    <xacro:property name="wheel_offset_x" value="0.40"/>
    <xacro:property name="wheel_offset_y" value="0.255"/>

    <xacro:property name="caster_wheel_radius" value="0.038"/>
    <xacro:property name="caster_wheel_mass" value="0.01"/>
    <xacro:property name="caster_z_offset" value="-0.062"/>

    <material name="white"><color rgba="1 1 1 1" /></material>
    <material name="black"><color rgba="0 0 0 1"/></material>
    <material name="red"><color rgba="1 0 0 1"/></material>

    <link name="base_footprint"/>

    <joint name="base_footprint_joint" type="fixed">
        <parent link="base_footprint"/>
        <child link="base_link"/>
        <origin xyz="0 0 ${wheel_radius}" rpy="0 0 0"/>
    </joint>

    <link name="base_link">
        <visual>
            <origin xyz="${(chassis_length/2) - wheel_offset_x} 0 ${chassis_height/2}"/>
            <geometry>
                <box size="${chassis_length} ${chassis_width} ${chassis_height}"/>
            </geometry>
            <material name="white"/>
        </visual>
        <collision>
            <origin xyz="${(chassis_length/2) - wheel_offset_x} 0 ${chassis_height/2}"/>
            <geometry>
                <box size="${chassis_length} ${chassis_width} ${chassis_height}"/>
            </geometry>
        </collision>
        <xacro:inertial_box mass="${chassis_mass}" x="${chassis_length}" y="${chassis_width}" z="${chassis_height}">
            <origin xyz="${(chassis_length/2) - wheel_offset_x} 0 ${chassis_height/2}" rpy="0 0 0"/>
        </xacro:inertial_box>
    </link>

    <gazebo reference="base_link">
        <material>Gazebo/White</material>
    </gazebo>

    <joint name="left_wheel_joint" type="continuous">
        <parent link="base_link"/>
        <child link="left_wheel"/>
        <origin xyz="0 ${wheel_offset_y} 0" rpy="-${pi/2} 0 0" />
        <axis xyz="0 0 1"/>
    </joint>

    <link name="left_wheel">
        <visual>
            <geometry><cylinder radius="${wheel_radius}" length="${wheel_thickness}"/></geometry>
            <material name="black"/>
        </visual>
        <collision>
            <geometry><sphere radius="${wheel_radius}"/></geometry>
        </collision>
        <xacro:inertial_cylinder mass="${wheel_mass}" length="${wheel_thickness}" radius="${wheel_radius}">
            <origin xyz="0 0 0" rpy="0 0 0"/>
        </xacro:inertial_cylinder>
    </link>

    <joint name="right_wheel_joint" type="continuous">
        <parent link="base_link"/>
        <child link="right_wheel"/>
        <origin xyz="0 ${-wheel_offset_y} 0" rpy="${pi/2} 0 0" />
        <axis xyz="0 0 -1"/>
    </joint>

    <link name="right_wheel">
        <visual>
            <geometry><cylinder radius="${wheel_radius}" length="${wheel_thickness}"/></geometry>
            <material name="black"/>
        </visual>
        <collision>
            <geometry><sphere radius="${wheel_radius}"/></geometry>
        </collision>
        <xacro:inertial_cylinder mass="${wheel_mass}" length="${wheel_thickness}" radius="${wheel_radius}">
            <origin xyz="0 0 0" rpy="0 0 0"/>
        </xacro:inertial_cylinder>
    </link>

    <joint name="caster_front_left_joint" type="fixed">
        <parent link="base_link"/>
        <child link="caster_front_left"/>
        <origin xyz="${0.75 - wheel_offset_x} 0.20 ${caster_z_offset}"/>
    </joint>
    <link name="caster_front_left">
        <visual>
            <geometry><sphere radius="${caster_wheel_radius}"/></geometry>
            <material name="red"/>
        </visual>
        <collision>
            <geometry><sphere radius="${caster_wheel_radius}"/></geometry>
        </collision>
        <xacro:inertial_sphere mass="${caster_wheel_mass}" radius="${caster_wheel_radius}">
            <origin xyz="0 0 0" rpy="0 0 0"/>
        </xacro:inertial_sphere>
    </link>

    <joint name="caster_front_right_joint" type="fixed">
        <parent link="base_link"/>
        <child link="caster_front_right"/>
        <origin xyz="${0.75 - wheel_offset_x} -0.20 ${caster_z_offset}"/>
    </joint>
    <link name="caster_front_right">
        <visual>
            <geometry><sphere radius="${caster_wheel_radius}"/></geometry>
            <material name="red"/>
        </visual>
        <collision>
            <geometry><sphere radius="${caster_wheel_radius}"/></geometry>
        </collision>
        <xacro:inertial_sphere mass="${caster_wheel_mass}" radius="${caster_wheel_radius}">
            <origin xyz="0 0 0" rpy="0 0 0"/>
        </xacro:inertial_sphere>
    </link>

    <joint name="caster_rear_left_joint" type="fixed">
        <parent link="base_link"/>
        <child link="caster_rear_left"/>
        <origin xyz="${0.05 - wheel_offset_x} 0.20 ${caster_z_offset}"/>
    </joint>
    <link name="caster_rear_left">
        <visual>
            <geometry><sphere radius="${caster_wheel_radius}"/></geometry>
            <material name="red"/>
        </visual>
        <collision>
            <geometry><sphere radius="${caster_wheel_radius}"/></geometry>
        </collision>
        <xacro:inertial_sphere mass="${caster_wheel_mass}" radius="${caster_wheel_radius}">
            <origin xyz="0 0 0" rpy="0 0 0"/>
        </xacro:inertial_sphere>
    </link>

    <joint name="caster_rear_right_joint" type="fixed">
        <parent link="base_link"/>
        <child link="caster_rear_right"/>
        <origin xyz="${0.05 - wheel_offset_x} -0.20 ${caster_z_offset}"/>
    </joint>
    <link name="caster_rear_right">
        <visual>
            <geometry><sphere radius="${caster_wheel_radius}"/></geometry>
            <material name="red"/>
        </visual>
        <collision>
            <geometry><sphere radius="${caster_wheel_radius}"/></geometry>
        </collision>
        <xacro:inertial_sphere mass="${caster_wheel_mass}" radius="${caster_wheel_radius}">
            <origin xyz="0 0 0" rpy="0 0 0"/>
        </xacro:inertial_sphere>
    </link>

    <joint name="imu_joint" type="fixed">
        <parent link="base_link"/>
        <child link="imu_link"/>
        <origin xyz="${0.4 - wheel_offset_x} 0 0.10" rpy="0 0 0"/>
    </joint>

    <link name="imu_link">
        <visual>
            <geometry><box size="0.0538 0.0488 0.0252"/></geometry>
            <material name="red"/>
        </visual>
        <collision>
            <geometry><box size="0.0538 0.0488 0.0252"/></geometry>
        </collision>
        <inertial>
            <mass value="0.01"/>
            <origin xyz="0 0 0" rpy="0 0 0"/>
            <inertia ixx="0.0001" ixy="0" ixz="0" iyy="0.0001" iyz="0" izz="0.0001"/>
        </inertial>
    </link>

</robot>